Workbook

Sheet Setup
H1: Days used for FBA Bounds | L1: Flasks = | M1: 6
B2: Initial Volume = | C2: 30 | D2: mL | H2: Stationary phase | L2: Total CD-CHO = | M2: =M1*I4 -> 180
B3: Daily Sampling = | C3: =B6 -> 1.5 | D3: mL | E3: CO2 | F3: Temperature | G3: Feed | H3: Day | I3: Volume | J3: % Change from 30mL | L3: Total FeedC = | M3: =M1*C4*SUM(G4:G18) -> 126
B4: Feed = | C4: =0.1*C2 -> 3 | D4: mL | E4: 0.08 | F4: 36.5 | G4: 0 | H4: 0 | I4: =C2 -> 30 | J4: =(I4-$C$2)/$C$2 -> 0
E5: 0.08 | F5: 36.5 | G5: 0 | H5: 1 | I5: =I4-$C$3+IF(G5=1,$C$4,0) -> 28.5 | J5: =(I5-$C$2)/$C$2 -> -0.05
A6: Daily Smapling = | B6: =C4/2 -> 1.5 | C6: ml | E6: 0.08 | F6: 36.5 | G6: 1 | H6: 2 | I6: =I5-$C$3+IF(G6=1,$C$4,0) -> 30 | J6: =(I6-$C$2)/$C$2 -> 0
A7: Cell counting | B7: 100 | C7: μl | E7: 0.08 | F7: 36.5 | G7: 0 | H7: 3 | I7: =I6-$C$3+IF(G7=1,$C$4,0) -> 28.5 | J7: =(I7-$C$2)/$C$2 -> -0.05
A8: Antinody titre quantification | B8: 4 | C8: μl | E8: 0.08 | F8: 32.5 | G8: 1 | H8: 4 | I8: =I7-$C$3+IF(G8=1,$C$4,0) -> 30 | J8: =(I8-$C$2)/$C$2 -> 0
A9: HPLC A.A analysis | B9: 100 | C9: μl | E9: 0.08 | F9: 32.5 | G9: 0 | H9: 5 | I9: =I8-$C$3+IF(G9=1,$C$4,0) -> 28.5 | J9: =(I9-$C$2)/$C$2 -> -0.05
A10: Rest to keep the volume steady | B10: =B6*1000-B7-B8-B9 -> 1296 | C10: μl | E10: 0.08 | F10: 32.5 | G10: 1 | H10: 6 | I10: =I9-$C$3+IF(G10=1,$C$4,0) -> 30 | J10: =(I10-$C$2)/$C$2 -> 0
E11: 0.08 | F11: 32.5 | G11: 0 | H11: 7 | I11: =I10-$C$3+IF(G11=1,$C$4,0) -> 28.5 | J11: =(I11-$C$2)/$C$2 -> -0.05
E12: 0.08 | F12: 32.5 | G12: 1 | H12: 8 | I12: =I11-$C$3+IF(G12=1,$C$4,0) -> 30 | J12: =(I12-$C$2)/$C$2 -> 0
E13: 0.08 | F13: 32.5 | G13: 0 | H13: 9 | I13: =I12-$C$3+IF(G13=1,$C$4,0) -> 28.5 | J13: =(I13-$C$2)/$C$2 -> -0.05
E14: 0.08 | F14: 32.5 | G14: 1 | H14: 10 | I14: =I13-$C$3+IF(G14=1,$C$4,0) -> 30 | J14: =(I14-$C$2)/$C$2 -> 0
E15: 0.08 | F15: 32.5 | G15: 0 | H15: 11 | I15: =I14-$C$3+IF(G15=1,$C$4,0) -> 28.5 | J15: =(I15-$C$2)/$C$2 -> -0.05
E16: 0.08 | F16: 32.5 | G16: 1 | H16: 12 | I16: =I15-$C$3+IF(G16=1,$C$4,0) -> 30 | J16: =(I16-$C$2)/$C$2 -> 0
E17: 0.08 | F17: 32.5 | G17: 0 | H17: 13 | I17: =I16-$C$3+IF(G17=1,$C$4,0) -> 28.5 | J17: =(I17-$C$2)/$C$2 -> -0.05
E18: 0.08 | F18: 32.5 | G18: 1 | H18: 14 | I18: =I17-$C$3+IF(G18=1,$C$4,0) -> 30 | J18: =(I18-$C$2)/$C$2 -> 0
J19: {=SUM(ABS(J4:J18))} -> 0.35

Sheet Results
C2: CHO_GS46'
C3: 1 | N3: 2
A4: Temperature | B4: Feed | C4: Day | E4: VCD (1E6 cells/mL) | F4: DCD | G4: Viability | H4: Integral of Viable Cell Concentration (IVCC) | I4: Daily Growth Rate | K4: Titre, g/l | L4: Sp. Q. pg/cell/day | N4: Day | P4: VCD (1E6 cells/mL) | Q4: DCD | R4: Viability | S4: Integral of Viable Cell Concentration (IVCC) | T4: Daily Growth Rate | V4: Titre, g/l | W4: Sp. Q. pg/cell/day
A5: 36.5 | B5: 0 | C5: 0 | D5: =C5*24 -> 0 | E5: =2*10^5/10^6 -> 0.2 | F5: 0 | G5: =E5/SUM(E5:F5) -> 1 | H5: 0 | I5: 0 | K5: 0.00443 | N5: 0 | O5: =N5*24 -> 0 | P5: =2*10^5/10^6 -> 0.2 | Q5: 0 | R5: =P5/SUM(P5:Q5) -> 1 | S5: 0 | T5: 0 | V5: 0.0045
A6: 36.5 | B6: 0 | C6: 1 | D6: =C6*24 -> 24 | E6: =134*4/10*10^4/10^6 -> 0.536 | F6: =7*4/10*10^4/10^6 -> 0.028 | G6: =E6/SUM(E6:F6) -> 0.95035461 | H6: =((E6+E5))/2*(D6-D5)+H5 -> 8.832 | I6: =(LN(E6)-LN(E5))/(D6-D5) -> 0.0410757 | K6: 0.01946 | L6: =((K6-K5)/(E6-E5))*I6*24000 -> 44.097698 | N6: 1 | O6: =N6*24 -> 24 | P6: =126*4/10*10^4/10^6 -> 0.504 | Q6: =6*4/10*10^4/10^6 -> 0.024 | R6: =P6/SUM(P6:Q6) -> 0.95454545 | S6: =((P6+P5))/2*(O6-O5)+S5 -> 8.448 | T6: =(LN(P6)-LN(P5))/(O6-O5) -> 0.038510788 | V6: 0.01865 | W6: =((V6-V5)/(P6-P5))*T6*24000 -> 43.020603
A7: 36.5 | B7: 1 | C7: 2 | D7: =C7*24 -> 48 | E7: =120*8/10*10^4/10^6 -> 0.96 | F7: =4*8/10*10^4/10^6 -> 0.032 | G7: =E7/SUM(E7:F7) -> 0.96774194 | H7: =((E7+E6))/2*(D7-D6)+H6 -> 26.784 | I7: =(LN(E7)-LN(E6))/(D7-D6) -> 0.024283297 | K7: 0.03872 | L7: =((K7-K6)/(E7-E6))*I7*24000 -> 26.473375 | N7: 2 | O7: =N7*24 -> 48 | P7: =160*8/10*10^4/10^6 -> 1.28 | Q7: =12*8/10*10^4/10^6 -> 0.096 | R7: =P7/SUM(P7:Q7) -> 0.93023256 | S7: =((P7+P6))/2*(O7-O6)+S6 -> 29.856 | T7: =(LN(P7)-LN(P6))/(O7-O6) -> 0.038834962 | V7: 0.04585 | W7: =((V7-V6)/(P7-P6))*T7*24000 -> 32.669411
A8: 36.5 | B8: 0 | C8: 3 | D8: =C8*24 -> 72 | E8: =110*10/10*10^4/10^6 -> 1.1 | F8: =33*10/10*10^4/10^6 -> 0.33 | G8: =E8/SUM(E8:F8) -> 0.76923077 | H8: =((E8+E7))/2*(D8-D7)+H7 -> 51.504 | I8: =(LN(E8)-LN(E7))/(D8-D7) -> 0.0056721739 | K8: 0.06155 | L8: =((K8-K7)/(E8-E7))*I8*24000 -> 22.199268 | N8: 3 | O8: =N8*24 -> 72 | P8: =120*10/10*10^4/10^6 -> 1.2 | Q8: =8*10/10*10^4/10^6 -> 0.08 | R8: =P8/SUM(P8:Q8) -> 0.9375 | S8: =((P8+P7))/2*(O8-O7)+S7 -> 59.616 | T8: =(LN(P8)-LN(P7))/(O8-O7) -> -0.002689105 | V8: 0.08366 | W8: =((V8-V7)/(P8-P7))*T8*24000 -> 30.502519
A9: 32.5 | B9: 1 | C9: 4 | D9: =C9*24 -> 96 | E9: =161*20/10*10^4/10^6 -> 3.22 | F9: =5*20/10*10^4/10^6 -> 0.1 | G9: =E9/SUM(E9:F9) -> 0.96987952 | H9: =((E9+E8))/2*(D9-D8)+H8 -> 103.344 | I9: =(LN(E9)-LN(E8))/(D9-D8) -> 0.044752966 | K9: 0.2215 | L9: =((K9-K8)/(E9-E8))*I9*24000 -> 81.036644 | N9: 4 | O9: =N9*24 -> 96 | P9: =160*20/10*10^4/10^6 -> 3.2 | Q9: =0*20/10*10^4/10^6 -> 0 | R9: =0*20/10*10^4/10^6 -> 0 | S9: =((P9+P8))/2*(O9-O8)+S8 -> 112.416 | T9: =(LN(P9)-LN(P8))/(O9-O8) -> 0.040867886 | V9: 0.217 | W9: =((V9-V8)/(P9-P8))*T9*24000 -> 65.391886
A10: 32.5 | B10: 0 | C10: 5 | D10: =C10*24 -> 120 | E10: =203*32/10*10^4/10^6 -> 6.496 | F10: =0*20/10*10^4/10^6 -> 0 | G10: =E10/SUM(E10:F10) -> 1 | H10: =((E10+E9))/2*(D10-D9)+H9 -> 219.936 | I10: =(LN(E10)-LN(E9))/(D10-D9) -> 0.029241885 | K10: 0.3821 | L10: =((K10-K9)/(E10-E9))*I10*24000 -> 34.404738 | N10: 5 | O10: =N10*24 -> 120 | P10: =210*32/10*10^4/10^6 -> 6.72 | Q10: =3*32/10*10^4/10^6 -> 0.096 | R10: =P10/SUM(P10:Q10) -> 0.98591549 | S10: =((P10+P9))/2*(O10-O9)+S9 -> 231.456 | T10: =(LN(P10)-LN(P9))/(O10-O9) -> 0.030914056 | V10: 0.35 | W10: =((V10-V9)/(P10-P9))*T10*24000 -> 28.033428
A11: 32.5 | B11: 1 | C11: 6 | D11: =C11*24 -> 144 | E11: =220*40/10*10^4/10^6 -> 8.8 | F11: =0*20/10*10^4/10^6 -> 0 | G11: =E11/SUM(E11:F11) -> 1 | H11: =((E11+E10))/2*(D11-D10)+H10 -> 403.488 | I11: =(LN(E11)-LN(E10))/(D11-D10) -> 0.012648547 | K11: 0.672 | L11: =((K11-K10)/(E11-E10))*I11*24000 -> 38.195976 | N11: 6 | O11: =N11*24 -> 144 | P11: =180*40/10*10^4/10^6 -> 7.2 | Q11: =0*32/10*10^4/10^6 -> 0 | R11: =P11/SUM(P11:Q11) -> 1 | S11: =((P11+P10))/2*(O11-O10)+S10 -> 398.496 | T11: =(LN(P11)-LN(P10))/(O11-O10) -> 0.002874703 | V11: 0.4919 | W11: =((V11-V10)/(P11-P10))*T11*24000 -> 20.396018
A12: 32.5 | B12: 0 | C12: 7 | D12: =C12*24 -> 168 | E12: =206*50/10*10^4/10^6 -> 10.3 | F12: =0*20/10*10^4/10^6 -> 0 | G12: =E12/SUM(E12:F12) -> 1 | H12: =((E12+E11))/2*(D12-D11)+H11 -> 632.688 | I12: =(LN(E12)-LN(E11))/(D12-D11) -> 0.0065580072 | K12: 0.7682 | L12: =((K12-K11)/(E12-E11))*I12*24000 -> 10.094085 | N12: 7 | O12: =N12*24 -> 168 | P12: =215*50/10*10^4/10^6 -> 10.75 | Q12: =0*32/10*10^4/10^6 -> 0 | R12: =P12/SUM(P12:Q12) -> 1 | S12: =((P12+P11))/2*(O12-O11)+S11 -> 613.896 | T12: =(LN(P12)-LN(P11))/(O12-O11) -> 0.01670103 | V12: 0.8191 | W12: =((V12-V11)/(P12-P11))*T12*24000 -> 36.94362
A13: 32.5 | B13: 1 | C13: 8 | D13: =C13*24 -> 192 | E13: =219*50/10*10^4/10^6 -> 10.95 | F13: =0*20/10*10^4/10^6 -> 0 | G13: =E13/SUM(E13:F13) -> 1 | H13: =((E13+E12))/2*(D13-D12)+H12 -> 887.688 | I13: =(LN(E13)-LN(E12))/(D13-D12) -> 0.002549815 | K13: 1.116 | L13: =((K13-K12)/(E13-E12))*I13*24000 -> 32.744333 | N13: 8 | O13: =N13*24 -> 192 | P13: =210*50/10*10^4/10^6 -> 10.5 | Q13: =0*32/10*10^4/10^6 -> 0 | R13: =P13/SUM(P13:Q13) -> 1 | S13: =((P13+P12))/2*(O13-O12)+S12 -> 868.896 | T13: =(LN(P13)-LN(P12))/(O13-O12) -> -0.00098043739 | V13: 1.398 | W13: =((V13-V12)/(P13-P12))*T13*24000 -> 54.48722
A14: 32.5 | B14: 0 | C14: 9 | D14: =C14*24 -> 216 | E14: =204*50/10*10^4/10^6 -> 10.2 | F14: =12*50/10*10^4/10^6 -> 0.6 | G14: =E14/SUM(E14:F14) -> 0.94444444 | H14: =((E14+E13))/2*(D14-D13)+H13 -> 1141.488 | I14: =(LN(E14)-LN(E13))/(D14-D13) -> -0.0029563223 | K14: 1.423 | L14: =((K14-K13)/(E14-E13))*I14*24000 -> 29.042911 | N14: 9 | O14: =N14*24 -> 216 | P14: =215*50/10*10^4/10^6 -> 10.75 | Q14: =7*50/10*10^4/10^6 -> 0.35 | R14: =P14/SUM(P14:Q14) -> 0.96846847 | S14: =((P14+P13))/2*(O14-O13)+S13 -> 1123.896 | T14: =(LN(P14)-LN(P13))/(O14-O13) -> 0.00098043739 | V14: 1.586 | W14: =((V14-V13)/(P14-P13))*T14*24000 -> 17.694934
A15: 32.5 | B15: 1 | C15: 10 | D15: =C15*24 -> 240 | E15: =209*50/10*10^4/10^6 -> 10.45 | F15: =14*50/10*10^4/10^6 -> 0.7 | G15: =E15/SUM(E15:F15) -> 0.93721973 | H15: =((E15+E14))/2*(D15-D14)+H14 -> 1389.288 | I15: =(LN(E15)-LN(E14))/(D15-D14) -> 0.0010089274 | K15: 1.878 | L15: =((K15-K14)/(E15-E14))*I15*24000 -> 44.06995 | N15: 10 | O15: =N15*24 -> 240 | P15: =200*50/10*10^4/10^6 -> 10 | Q15: =12*50/10*10^4/10^6 -> 0.6 | R15: =P15/SUM(P15:Q15) -> 0.94339623 | S15: =((P15+P14))/2*(O15-O14)+S14 -> 1372.896 | T15: =(LN(P15)-LN(P14))/(O15-O14) -> -0.0030133609 | V15: 1.751 | W15: =((V15-V14)/(P15-P14))*T15*24000 -> 15.910546
A16: 32.5 | B16: 0 | C16: 11 | D16: =C16*24 -> 264 | E16: =220*50/10*10^4/10^6 -> 11 | F16: =39*50/10*10^4/10^6 -> 1.95 | G16: =E16/SUM(E16:F16) -> 0.84942085 | H16: =((E16+E15))/2*(D16-D15)+H15 -> 1646.688 | I16: =(LN(E16)-LN(E15))/(D16-D15) -> 0.0021372206 | K16: 1.965 | L16: =((K16-K15)/(E16-E15))*I16*24000 -> 8.1136666 | N16: 11 | O16: =N16*24 -> 264 | P16: =191*50/10*10^4/10^6 -> 9.55 | Q16: =32*50/10*10^4/10^6 -> 1.6 | R16: =P16/SUM(P16:Q16) -> 0.85650224 | S16: =((P16+P15))/2*(O16-O15)+S15 -> 1607.496 | T16: =(LN(P16)-LN(P15))/(O16-O15) -> -0.0019184974 | V16: 2.024 | W16: =((V16-V15)/(P16-P15))*T16*24000 -> 27.933323
A17: 32.5 | B17: 1 | C17: 12 | D17: =C17*24 -> 288 | E17: =182*50/10*10^4/10^6 -> 9.1 | F17: =19*50/10*10^4/10^6 -> 0.95 | G17: =E17/SUM(E17:F17) -> 0.90547264 | H17: =((E17+E16))/2*(D17-D16)+H16 -> 1887.888 | I17: =(LN(E17)-LN(E16))/(D17-D16) -> -0.0079008691 | K17: 1.88 | L17: =((K17-K16)/(E17-E16))*I17*24000 -> -8.4830384 | N17: 12 | O17: =N17*24 -> 288 | P17: =156*50/10*10^4/10^6 -> 7.8 | Q17: =31*50/10*10^4/10^6 -> 1.55 | R17: =P17/SUM(P17:Q17) -> 0.8342246 | S17: =((P17+P16))/2*(O17-O16)+S16 -> 1815.696 | T17: =(LN(P17)-LN(P16))/(O17-O16) -> -0.0084340592 | V17: 1.879 | W17: =((V17-V16)/(P17-P16))*T17*24000 -> -16.771729
A18: 32.5 | B18: 0 | C18: 13 | D18: =C18*24 -> 312 | E18: =145*50/10*10^4/10^6 -> 7.25 | F18: =17*50/10*10^4/10^6 -> 0.85 | G18: =E18/SUM(E18:F18) -> 0.89506173 | H18: =((E18+E17))/2*(D18-D17)+H17 -> 2084.088 | I18: =(LN(E18)-LN(E17))/(D18-D17) -> -0.009469706 | K18: 1.814 | L18: =((K18-K17)/(E18-E17))*I18*24000 -> -8.1081159 | N18: 13 | O18: =N18*24 -> 312 | P18: =176*50/10*10^4/10^6 -> 8.8 | Q18: =30*50/10*10^4/10^6 -> 1.5 | R18: =P18/SUM(P18:Q18) -> 0.85436893 | S18: =((P18+P17))/2*(O18-O17)+S17 -> 2014.896 | T18: =(LN(P18)-LN(P17))/(O18-O17) -> 0.0050261662 | V18: 1.895 | W18: =((V18-V17)/(P18-P17))*T18*24000 -> 1.9300478
A19: 32.5 | B19: 0 | C19: 14 | D19: =C19*24 -> 336 | E19: =129*40/10*10^4/10^6 -> 5.16 | F19: =55*40/10*10^4/10^6 -> 2.2 | G19: =E19/SUM(E19:F19) -> 0.70108696 | H19: =((E19+E18))/2*(D19-D18)+H18 -> 2233.008 | I19: =(LN(E19)-LN(E18))/(D19-D18) -> -0.01416937 | K19: 1.802 | L19: =((K19-K18)/(E19-E18))*I19*24000 -> -1.9525257 | N19: 14 | O19: =N19*24 -> 336 | P19: =151*40/10*10^4/10^6 -> 6.04 | Q19: =56*40/10*10^4/10^6 -> 2.24 | R19: =P19/SUM(P19:Q19) -> 0.7294686 | S19: =((P19+P18))/2*(O19-O18)+S18 -> 2192.976 | T19: =(LN(P19)-LN(P18))/(O19-O18) -> -0.015681155 | V19: 1.764 | W19: =((V19-V18)/(P19-P18))*T19*24000 -> -17.86288
C24: CHO_GS46
C25: 1 | K25: IgG | N25: 2 | V25: IgG
A26: Temperature | B26: Feed | C26: Day | E26: VCD (1E6 cells/mL) | F26: DCD | G26: Viability | H26: Integral of Viable Cell Concentration (IVCC) | I26: Daily Growth Rate | K26: Titre, g/l | L26: Sp. Q. pg/cell/day | N26: Day | P26: VCD (1E6 cells/mL) | Q26: DCD | R26: Viability | S26: Integral of Viable Cell Concentration (IVCC) | T26: Daily Growth Rate | V26: Titre, g/l | W26: Sp. Q. pg/cell/day
A27: 36.5 | B27: 0 | C27: 0 | D27: =C27*24 -> 0 | E27: =2*10^5/10^6 -> 0.2 | F27: 0 | G27: =E27/SUM(E27:F27) -> 1 | H27: 0 | I27: 0 | K27: 0.003536209 | N27: 0 | O27: =N27*24 -> 0 | P27: =2*10^5/10^6 -> 0.2 | Q27: 0 | R27: =P27/SUM(P27:Q27) -> 1 | S27: 0 | T27: 0 | V27: 0.0025
A28: 36.5 | B28: 0 | C28: 1 | D28: =C28*24 -> 24 | E28: =105*4/10*10^4/10^6 -> 0.42 | F28: =4*4/10*10^4/10^6 -> 0.016 | G28: =E28/SUM(E28:F28) -> 0.96330275 | H28: =((E28+E27))/2*(D28-D27)+H27 -> 7.44 | I28: =(LN(E28)-LN(E27))/(D28-D27) -> 0.030914056 | K28: 0.01755 | L28: =((K28-K27)/(E28-E27))*I28*24000 -> 47.260704 | N28: 1 | O28: =N28*24 -> 24 | P28: =84*4/10*10^4/10^6 -> 0.336 | Q28: =(5)*4/10*10^4/10^6 -> 0.02 | R28: =P28/SUM(P28:Q28) -> 0.94382022 | S28: =((P28+P27))/2*(O28-O27)+S27 -> 6.432 | T28: =(LN(P28)-LN(P27))/(O28-O27) -> 0.021616408 | V28: 0.01723 | W28: =((V28-V27)/(P28-P27))*T28*24000 -> 56.189945
A29: 36.5 | B29: 1 | C29: 2 | D29: =C29*24 -> 48 | E29: =135*6/10*10^4/10^6 -> 0.81 | F29: =2*6/10*10^4/10^6 -> 0.012 | G29: =E29/SUM(E29:F29) -> 0.98540146 | H29: =((E29+E28))/2*(D29-D28)+H28 -> 22.2 | I29: =(LN(E29)-LN(E28))/(D29-D28) -> 0.027365814 | K29: 0.02992 | L29: =((K29-K28)/(E29-E28))*I29*24000 -> 20.8317 | N29: 2 | O29: =N29*24 -> 48 | P29: =97*8/10*10^4/10^6 -> 0.776 | Q29: =(3)*8/10*10^4/10^6 -> 0.024 | R29: =P29/SUM(P29:Q29) -> 0.97 | S29: =((P29+P28))/2*(O29-O28)+S28 -> 19.776 | T29: =(LN(P29)-LN(P28))/(O29-O28) -> 0.034876723 | V29: 0.03522 | W29: =((V29-V28)/(P29-P28))*T29*24000 -> 34.223577
A30: 36.5 | B30: 0 | C30: 3 | D30: =C30*24 -> 72 | E30: =85*20/10*10^4/10^6 -> 1.7 | F30: =4*4/10*10^4/10^6 -> 0.016 | G30: =E30/SUM(E30:F30) -> 0.99067599 | H30: =((E30+E29))/2*(D30-D29)+H29 -> 52.32 | I30: =(LN(E30)-LN(E29))/(D30-D29) -> 0.030889553 | K30: 0.06472 | L30: =((K30-K29)/(E30-E29))*I30*24000 -> 28.98759 | N30: 3 | O30: =N30*24 -> 72 | P30: =63*20/10*10^4/10^6 -> 1.26 | Q30: =(7)*10/10*10^4/10^6 -> 0.07 | R30: =P30/SUM(P30:Q30) -> 0.94736842 | S30: =((P30+P29))/2*(O30-O29)+S29 -> 44.208 | T30: =(LN(P30)-LN(P29))/(O30-O29) -> 0.020196437 | V30: 0.06388 | W30: =((V30-V29)/(P30-P29))*T30*24000 -> 28.702308
A31: 32.5 | B31: 1 | C31: 4 | D31: =C31*24 -> 96 | E31: =300*20/10*10^4/10^6 -> 6 | F31: =33*0/10*10^4/10^6 -> 0 | G31: =E31/SUM(E31:F31) -> 1 | H31: =((E31+E30))/2*(D31-D30)+H30 -> 144.72 | I31: =(LN(E31)-LN(E30))/(D31-D30) -> 0.052547134 | K31: 0.1567 | L31: =((K31-K30)/(E31-E30))*I31*24000 -> 26.976477 | N31: 4 | O31: =N31*24 -> 96 | P31: =117*32/10*10^4/10^6 -> 3.744 | Q31: =33*0/10*10^4/10^6 -> 0 | R31: =P31/SUM(P31:Q31) -> 1 | S31: =((P31+P30))/2*(O31-O30)+S30 -> 104.256 | T31: =(LN(P31)-LN(P30))/(O31-O30) -> 0.045376785 | V31: 0.1537 | W31: =((V31-V30)/(P31-P30))*T31*24000 -> 39.379158
A32: 32.5 | B32: 0 | C32: 5 | D32: =C32*24 -> 120 | E32: =165*36/10*10^4/10^6 -> 5.94 | F32: =33*0/10*10^4/10^6 -> 0 | G32: =E32/SUM(E32:F32) -> 1 | H32: =((E32+E31))/2*(D32-D31)+H31 -> 288 | I32: =(LN(E32)-LN(E31))/(D32-D31) -> -0.00041876399 | K32: 0.2547 | L32: =((K32-K31)/(E32-E31))*I32*24000 -> 16.415549 | N32: 5 | O32: =N32*24 -> 120 | P32: =110*36/10*10^4/10^6 -> 3.96 | Q32: =5*36/10*10^4/10^6 -> 0.18 | R32: =P32/SUM(P32:Q32) -> 0.95652174 | S32: =((P32+P31))/2*(O32-O31)+S31 -> 196.704 | T32: =(LN(P32)-LN(P31))/(O32-O31) -> 0.0023370611 | V32: 0.2394 | W32: =((V32-V31)/(P32-P31))*T32*24000 -> 22.254015
A33: 32.5 | B33: 1 | C33: 6 | D33: =C33*24 -> 144 | E33: =170*40/10*10^4/10^6 -> 6.8 | F33: =33*0/10*10^4/10^6 -> 0 | G33: =E33/SUM(E33:F33) -> 1 | H33: =((E33+E32))/2*(D33-D32)+H32 -> 440.88 | I33: =(LN(E33)-LN(E32))/(D33-D32) -> 0.005633895 | K33: 0.4531 | L33: =((K33-K32)/(E33-E32))*I33*24000 -> 31.193435 | N33: 6 | O33: =N33*24 -> 144 | P33: =137*40/10*10^4/10^6 -> 5.48 | Q33: =0*10/10*10^4/10^6 -> 0 | R33: =P33/SUM(P33:Q33) -> 1 | S33: =((P33+P32))/2*(O33-O32)+S32 -> 309.984 | T33: =(LN(P33)-LN(P32))/(O33-O32) -> 0.013535878 | V33: 0.4472 | W33: =((V33-V32)/(P33-P32))*T33*24000 -> 44.411929
A34: 32.5 | B34: 0 | C34: 7 | D34: =C34*24 -> 168 | E34: =201*50/10*10^4/10^6 -> 10.05 | F34: =33*0/10*10^4/10^6 -> 0 | G34: =E34/SUM(E34:F34) -> 1 | H34: =((E34+E33))/2*(D34-D33)+H33 -> 643.08 | I34: =(LN(E34)-LN(E33))/(D34-D33) -> 0.016277084 | K34: 0.65 | L34: =((K34-K33)/(E34-E33))*I34*24000 -> 23.667381 | N34: 7 | O34: =N34*24 -> 168 | P34: =150*50/10*10^4/10^6 -> 7.5 | Q34: =0*10/10*10^4/10^6 -> 0 | R34: =P34/SUM(P34:Q34) -> 1 | S34: =((P34+P33))/2*(O34-O33)+S33 -> 465.744 | T34: =(LN(P34)-LN(P33))/(O34-O33) -> 0.013074913 | V34: 0.5677 | W34: =((V34-V33)/(P34-P33))*T34*24000 -> 18.719133
A35: 32.5 | B35: 1 | C35: 8 | D35: =C35*24 -> 192 | E35: =205*50/10*10^4/10^6 -> 10.25 | F35: =33*0/10*10^4/10^6 -> 0 | G35: =E35/SUM(E35:F35) -> 1 | H35: =((E35+E34))/2*(D35-D34)+H34 -> 886.68 | I35: =(LN(E35)-LN(E34))/(D35-D34) -> 0.00082104463 | K35: 0.752 | L35: =((K35-K34)/(E35-E34))*I35*24000 -> 10.049586 | N35: 8 | O35: =N35*24 -> 192 | P35: =185*50/10*10^4/10^6 -> 9.25 | Q35: =0*10/10*10^4/10^6 -> 0 | R35: =P35/SUM(P35:Q35) -> 1 | S35: =((P35+P34))/2*(O35-O34)+S34 -> 666.744 | T35: =(LN(P35)-LN(P34))/(O35-O34) -> 0.0087383555 | V35: 0.7055 | W35: =((V35-V34)/(P35-P34))*T35*24000 -> 16.513994
A36: 32.5 | B36: 0 | C36: 9 | D36: =C36*24 -> 216 | E36: =234*50/10*10^4/10^6 -> 11.7 | F36: =12*50/10*10^4/10^6 -> 0.6 | G36: =E36/SUM(E36:F36) -> 0.95121951 | H36: =((E36+E35))/2*(D36-D35)+H35 -> 1150.08 | I36: =(LN(E36)-LN(E35))/(D36-D35) -> 0.005512964 | K36: 0.922 | L36: =((K36-K35)/(E36-E35))*I36*24000 -> 15.51234 | N36: 9 | O36: =N36*24 -> 216 | P36: =200*50/10*10^4/10^6 -> 10 | Q36: =0*10/10*10^4/10^6 -> 0 | R36: =P36/SUM(P36:Q36) -> 1 | S36: =((P36+P35))/2*(O36-O35)+S35 -> 897.744 | T36: =(LN(P36)-LN(P35))/(O36-O35) -> 0.0032483976 | V36: 0.9469 | W36: =((V36-V35)/(P36-P35))*T36*24000 -> 25.093221
A37: 32.5 | B37: 1 | C37: 10 | D37: =C37*24 -> 240 | E37: =209*50/10*10^4/10^6 -> 10.45 | F37: =27*50/10*10^4/10^6 -> 1.35 | G37: =E37/SUM(E37:F37) -> 0.88559322 | H37: =((E37+E36))/2*(D37-D36)+H36 -> 1415.88 | I37: =(LN(E37)-LN(E36))/(D37-D36) -> -0.004707786 | K37: 1.244 | L37: =((K37-K36)/(E37-E36))*I37*24000 -> 29.105416 | N37: 10 | O37: =N37*24 -> 240 | P37: =213*50/10*10^4/10^6 -> 10.65 | Q37: =23*50/10*10^4/10^6 -> 1.15 | R37: =P37/SUM(P37:Q37) -> 0.90254237 | S37: =((P37+P36))/2*(O37-O36)+S36 -> 1145.544 | T37: =(LN(P37)-LN(P36))/(O37-O36) -> 0.00262395 | V37: 1.326 | W37: =((V37-V36)/(P37-P36))*T37*24000 -> 36.728841
A38: 32.5 | B38: 0 | C38: 11 | D38: =C38*24 -> 264 | E38: =163*50/10*10^4/10^6 -> 8.15 | F38: =14*50/10*10^4/10^6 -> 0.7 | G38: =E38/SUM(E38:F38) -> 0.92090395 | H38: =((E38+E37))/2*(D38-D37)+H37 -> 1639.08 | I38: =(LN(E38)-LN(E37))/(D38-D37) -> -0.010357669 | K38: 1.701 | L38: =((K38-K37)/(E38-E37))*I38*24000 -> 49.39257 | N38: 11 | O38: =N38*24 -> 264 | P38: =185*50/10*10^4/10^6 -> 9.25 | Q38: =30*40/10*10^4/10^6 -> 1.2 | R38: =P38/SUM(P38:Q38) -> 0.88516746 | S38: =((P38+P37))/2*(O38-O37)+S37 -> 1384.344 | T38: =(LN(P38)-LN(P37))/(O38-O37) -> -0.0058723475 | V38: 1.689 | W38: =((V38-V37)/(P38-P37))*T38*24000 -> 36.54278
A39: 32.5 | B39: 1 | C39: 12 | D39: =C39*24 -> 288 | E39: =150*50/10*10^4/10^6 -> 7.5 | F39: =12*50/10*10^4/10^6 -> 0.6 | G39: =E39/SUM(E39:F39) -> 0.92592593 | H39: =((E39+E38))/2*(D39-D38)+H38 -> 1826.88 | I39: =(LN(E39)-LN(E38))/(D39-D38) -> -0.0034631211 | K39: 1.75 | L39: =((K39-K38)/(E39-E38))*I39*24000 -> 6.2655853 | N39: 12 | O39: =N39*24 -> 288 | P39: =180*40/10*10^4/10^6 -> 7.2 | Q39: =23*40/10*10^4/10^6 -> 0.92 | R39: =P39/SUM(P39:Q39) -> 0.88669951 | S39: =((P39+P38))/2*(O39-O38)+S38 -> 1581.744 | T39: =(LN(P39)-LN(P38))/(O39-O38) -> -0.010439272 | V39: 2 | W39: =((V39-V38)/(P39-P38))*T39*24000 -> 38.009134
A40: 32.5 | B40: 0 | C40: 13 | D40: =C40*24 -> 312 | E40: =140*50/10*10^4/10^6 -> 7 | F40: =31*50/10*10^4/10^6 -> 1.55 | G40: =E40/SUM(E40:F40) -> 0.81871345 | H40: =((E40+E39))/2*(D40-D39)+H39 -> 2000.88 | I40: =(LN(E40)-LN(E39))/(D40-D39) -> -0.002874703 | K40: 1.795 | L40: =((K40-K39)/(E40-E39))*I40*24000 -> 6.2093584 | N40: 13 | O40: =N40*24 -> 312 | P40: =170*40/10*10^4/10^6 -> 6.8 | Q40: =39*40/10*10^4/10^6 -> 1.56 | R40: =P40/SUM(P40:Q40) -> 0.81339713 | S40: =((P40+P39))/2*(O40-O39)+S39 -> 1749.744 | T40: =(LN(P40)-LN(P39))/(O40-O39) -> -0.0023816006 | V40: 2.061 | W40: =((V40-V39)/(P40-P39))*T40*24000 -> 8.7166581
A41: 32.5 | B41: 0 | C41: 14 | D41: =C41*24 -> 336 | E41: =160*40/10*10^4/10^6 -> 6.4 | F41: =40*40/10*10^4/10^6 -> 1.6 | G41: =E41/SUM(E41:F41) -> 0.8 | H41: =((E41+E40))/2*(D41-D40)+H40 -> 2161.68 | I41: =(LN(E41)-LN(E40))/(D41-D40) -> -0.0037338399 | K41: 1.77 | L41: =((K41-K40)/(E41-E40))*I41*24000 -> -3.7338399 | N41: 14 | O41: =N41*24 -> 336 | P41: =173*40/10*10^4/10^6 -> 6.92 | Q41: =44*40/10*10^4/10^6 -> 1.76 | R41: =P41/SUM(P41:Q41) -> 0.79723502 | S41: =((P41+P40))/2*(O41-O40)+S40 -> 1914.384 | T41: =(LN(P41)-LN(P40))/(O41-O40) -> 0.00072888156 | V41: 1.918 | W41: =((V41-V40)/(P41-P40))*T41*24000 -> -20.846013
C46: CHO_GS46_B
C47: 1 | K47: IgG | N47: 2 | V47: IgG
A48: Temperature | B48: Feed | C48: Day | E48: VCD (1E6 cells/mL) | F48: DCD | G48: Viability | H48: Integral of Viable Cell Concentration (IVCC) | I48: Daily Growth Rate | K48: Titre, g/l | L48: Sp. Q. pg/cell/day | N48: Day | P48: VCD (1E6 cells/mL) | Q48: DCD | R48: Viability | S48: Integral of Viable Cell Concentration (IVCC) | T48: Daily Growth Rate | V48: Titre, g/l | W48: Sp. Q. pg/cell/day
A49: 36.5 | B49: 0 | C49: 0 | D49: =C49*24 -> 0 | E49: =2*10^5/10^6 -> 0.2 | F49: 0 | G49: =E49/SUM(E49:F49) -> 1 | H49: 0 | I49: 0 | K49: 0.0014536209 | N49: 0 | O49: =N49*24 -> 0 | P49: =2*10^5/10^6 -> 0.2 | Q49: 0 | R49: =P49/SUM(P49:Q49) -> 1 | S49: 0 | T49: 0 | V49: 0.003536209
...

Sheet FinalResults
C2: CHO-GS46' | P2: CHO-GS46 | AC2: CHO-GS46-B | AP2: 36.5C thought culture: CHO-GS46, Sarantos Feed C
C3: Day | D3: Hours | E3: VCD (1E6 cells/mL) | F3: VCD std | G3: Viability | H3: Integral of Viable Cell Concentration (IVCC) | I3: IVCD std | J3: Daily Growth Rate | K3: Titre, g/l | L3: Qp titer | M3: Sp. Q. pg/cell/day | N3: Qp Standard Deviation | P3: Day | Q3: Hours | R3: VCD (1E6 cells/mL) | S3: VCD std | T3: Viability | U3: Integral of Viable Cell Concentration (IVCC) | V3: IVCD std | W3: Daily Growth Rate | X3: Titre, g/l | Y3: Qp titer | Z3: Sp. Q. pg/cell/day | AA3: Qp Standard Deviation | AC3: Day | AD3: Hours | AE3: VCD (1E6 cells/mL) | AF3: VCD std | AG3: Viability | AH3: Integral of Viable Cell Concentration (IVCC) | AI3: IVCD std | AJ3: Daily Growth Rate | AK3: Titre, g/l | AL3: Qp titer | AM3: Sp. Q. pg/cell/day | AN3: Qp Standard Deviation | AP3: Day | AQ3: VCD (1E6 cells/mL) | AR3: VCD std | AS3: Titre, g/l | AT3: Qp titer | AU3: Sp. Q. pg/cell/day | AV3: Qp Standard Deviation
A4: Temperature | B4: Feed | C4: 0 | D4: =C4*24 -> 0 | E4: =(Results!E5+Results!P5)/2 -> 0.2 | F4: =_xlfn.STDEV.S(Results!E5,Results!P5) -> 0 | G4: =E4/SUM(E4:F4) -> 1 | H4: 0 | I4: =STDEV(Results!H5,Results!S5) -> 0 | J4: 0 | K4: =AVERAGE(Results!K5,Results!V5) -> 0.004465 | L4: =STDEV(Results!K5,Results!V5) -> 4.9497475e-05 | P4: 0 | Q4: =P4*24 -> 0 | R4: =(Results!E27+Results!P27)/2 -> 0.2 | S4: =_xlfn.STDEV.S(Results!E27,Results!P27) -> 0 | T4: =R4/SUM(R4:S4) -> 1 | U4: 0 | V4: =STDEV(Results!H27,Results!S27) -> 0 | W4: 0 | X4: =AVERAGE(Results!K27,Results!V27) -> 0.0030181045 | Y4: =STDEV(Results!K27,Results!V27) -> 0.00073271041 | AC4: 0 | AD4: =AC4*24 -> 0 | AE4: =(Results!E49+Results!P49)/2 -> 0.2 | AF4: =_xlfn.STDEV.S(Results!E49,Results!P49) -> 0 | AG4: =AE4/SUM(AE4:AF4) -> 1 | AH4: 0 | AI4: =STDEV(Results!H49,Results!S49) -> 0 | AJ4: 0 | AK4: =AVERAGE(Results!K49,Results!V49) -> 0.0024949149 | AL4: =STDEV(Results!K49,Results!V49) -> 0.0014726122 | AP4: 0 | AQ4: 0.2 | AR4: 0.01 | AS4: 0.004536209 | AT4: 0.001
A5: 36.5 | B5: 0 | C5: 1 | D5: =C5*24 -> 24 | E5: =(Results!E6+Results!P6)/2 -> 0.52 | F5: =_xlfn.STDEV.S(Results!E6,Results!P6) -> 0.022627417 | G5: =E5/SUM(E5:F5) -> 0.95830027 | H5: =((E5+E4))/2*(D5-D4)+H4 -> 8.64 | I5: =STDEV(Results!H6,Results!S6) -> 0.271529 | J5: =(LN(E5)-LN(E4))/(D5-D4) -> 0.039812977 | K5: =AVERAGE(Results!K6,Results!V6) -> 0.019055 | L5: =STDEV(Results!K6,Results!V6) -> 0.00057275649 | M5: =((K5-K4)/(E5-E4))*J5*24000 -> 43.56535 | N5: =STDEV(Results!L6,Results!W6) -> 0.76162062 | P5: 1 | Q5: =P5*24 -> 24 | R5: =(Results!E28+Results!P28)/2 -> 0.378 | S5: =_xlfn.STDEV.S(Results!E28,Results!P28) -> 0.05939697 | T5: =R5/SUM(R5:S5) -> 0.86420352 | U5: =((R5+R4))/2*(Q5-Q4)+U4 -> 6.936 | V5: =STDEV(Results!H28,Results!S28) -> 0.71276364 | W5: =(LN(R5)-LN(R4))/(Q5-Q4) -> 0.026524035 | X5: =AVERAGE(Results!K28,Results!V28) -> 0.01739 | Y5: =STDEV(Results!K28,Results!V28) -> 0.00022627417 | Z5: =((X5-X4)/(R5-R4))*W5*24000 -> 51.397841 | AA5: =STDEV(Results!W28,Results!L28) -> 6.3139271 | AC5: 1 | AD5: =AC5*24 -> 24 | AE5: =(Results!E50+Results!P50)/2 -> 0.396 | AF5: =_xlfn.STDEV.S(Results!E50,Results!P50) -> 0 | AG5: =AE5/SUM(AE5:AF5) -> 1 | AH5: =((AE5+AE4))/2*(AD5-AD4)+AH4 -> 7.152 | AI5: =STDEV(Results!H50,Results!S50) -> 0 | AJ5: =(LN(AE5)-LN(AE4))/(AD5-AD4) -> 0.028462369 | AK5: =AVERAGE(Results!K50,Results!V50) -> 0.012145 | AL5: =STDEV(Results!K50,Results!V50) -> 0.00012020815 | AM5: =((AK5-AK4)/(AE5-AE4))*AJ5*24000 -> 33.63236 | AN5: =STDEV(Results!L50,Results!W50) -> 4.7133822 | AP5: 1 | AQ5: 0.44073333 | AR5: 0.0092094155 | AS5: 0.009151864 | AT5: 0.001 | AU5: 15.149267 | AV5: 0
A6: 36.5 | B6: 0 | C6: 2 | D6: =C6*24 -> 48 | E6: =(Results!E7+Results!P7)/2 -> 1.12 | F6: =_xlfn.STDEV.S(Results!E7,Results!P7) -> 0.22627417 | G6: =E6/SUM(E6:F6) -> 0.83192564 | H6: =((E6+E5))/2*(D6-D5)+H5 -> 28.32 | I6: =STDEV(Results!H7,Results!S7) -> 2.172232 | J6: =(LN(E6)-LN(E5))/(D6-D5) -> 0.031968965 | K6: =AVERAGE(Results!K7,Results!V7) -> 0.042285 | L6: =STDEV(Results!K7,Results!V7) -> 0.0050416713 | M6: =((K6-K5)/(E6-E5))*J6*24000 -> 29.705562 | N6: =STDEV(Results!L7,Results!W7) -> 4.3812591 | P6: 2 | Q6: =P6*24 -> 48 | R6: =(Results!E29+Results!P29)/2 -> 0.793 | S6: =_xlfn.STDEV.S(Results!E29,Results!P29) -> 0.024041631 | T6: =R6/SUM(R6:S6) -> 0.97057478 | U6: =((R6+R5))/2*(Q6-Q5)+U5 -> 20.988 | V6: =STDEV(Results!H29,Results!S29) -> 1.7140268 | W6: =(LN(R6)-LN(R5))/(Q6-Q5) -> 0.030872043 | X6: =AVERAGE(Results!K29,Results!V29) -> 0.03257 | Y6: =STDEV(Results!K29,Results!V29) -> 0.0037476659 | Z6: =((X6-X5)/(R6-R5))*W6*24000 -> 27.101934 | AA6: =STDEV(Results!W29,Results!L29) -> 9.4694876 | AC6: 2 | AD6: =AC6*24 -> 48 | AE6: =(Results!E51+Results!P51)/2 -> 0.68 | AF6: =_xlfn.STDEV.S(Results!E51,Results!P51) -> 0.090509668 | AG6: =AE6/SUM(AE6:AF6) -> 0.88253273 | AH6: =((AE6+AE5))/2*(AD6-AD5)+AH5 -> 20.064 | AI6: =STDEV(Results!H51,Results!S51) -> 1.086116 | AJ6: =(LN(AE6)-LN(AE5))/(AD6-AD5) -> 0.022528274 | AK6: =AVERAGE(Results!K51,Results!V51) -> 0.024645 | AL6: =STDEV(Results!K51,Results!V51) -> 0.00094045202 | AM6: =((AK6-AK5)/(AE6-AE5))*AJ6*24000 -> 23.797473 | AN6: =STDEV(Results!L51,Results!W51) -> 3.300905 | AP6: 2 | AQ6: 0.926 | AR6: 0.045033321 | AS6: 0.018852142 | AT6: 0.001 | AU6: 14.84095 | AV6: 2.9019865
A7: 36.5 | B7: 1 | C7: 3 | D7: =C7*24 -> 72 | E7: =(Results!E8+Results!P8)/2 -> 1.15 | F7: =_xlfn.STDEV.S(Results!E8,Results!P8) -> 0.070710678 | G7: =E7/SUM(E7:F7) -> 0.94207417 | H7: =((E7+E6))/2*(D7-D6)+H6 -> 55.56 | I7: =STDEV(Results!H8,Results!S8) -> 5.7360502 | J7: =(LN(E7)-LN(E6))/(D7-D6) -> 0.0011013857 | K7: =AVERAGE(Results!K8,Results!V8) -> 0.072605 | L7: =STDEV(Results!K8,Results!V8) -> 0.015634131 | M7: =((K7-K6)/(E7-E6))*J7*24000 -> 26.715212 | N7: =STDEV(Results!L8,Results!W8) -> 5.8712847 | P7: 3 | Q7: =P7*24 -> 72 | R7: =(Results!E30+Results!P30)/2 -> 1.48 | S7: =_xlfn.STDEV.S(Results!E30,Results!P30) -> 0.31112698 | T7: =R7/SUM(R7:S7) -> 0.82629541 | U7: =((R7+R6))/2*(Q7-Q6)+U6 -> 48.264 | V7: =STDEV(Results!H30,Results!S30) -> 5.7360502 | W7: =(LN(R7)-LN(R6))/(Q7-Q6) -> 0.025998923 | X7: =AVERAGE(Results!K30,Results!V30) -> 0.0643 | Y7: =STDEV(Results!K30,Results!V30) -> 0.0005939697 | Z7: =((X7-X6)/(R7-R6))*W7*24000 -> 28.819068 | AA7: =STDEV(Results!W30,Results!L30) -> 0.2017249 | AC7: 3 | AD7: =AC7*24 -> 72 | AE7: =(Results!E52+Results!P52)/2 -> 0.935 | AF7: =_xlfn.STDEV.S(Results!E52,Results!P52) -> 0.049497475 | AG7: =AE7/SUM(AE7:AF7) -> 0.94972311 | AH7: =((AE7+AE6))/2*(AD7-AD6)+AH6 -> 39.444 | AI7: =STDEV(Results!H52,Results!S52) -> 1.5782623 | AJ7: =(LN(AE7)-LN(AE6))/(AD7-AD6) -> 0.013268905 | AK7: =AVERAGE(Results!K52,Results!V52) -> 0.05757 | AL7: =STDEV(Results!K52,Results!V52) -> 0.0063215346 | AM7: =((AK7-AK6)/(AE7-AE6))*AJ7*24000 -> 41.117996 | AN7: =STDEV(Results!L52,Results!W52) -> 7.6348379 | AP7: 3 | AQ7: 1.5831111 | AR7: 0.036401058 | AS7: 0.036649954 | AT7: 0.001 | AU7: 14.52492 | AV7: 2.2065367
A8: 36.5 | B8: 0 | C8: 4 | D8: =C8*24 -> 96 | E8: =(Results!E9+Results!P9)/2 -> 3.21 | F8: =_xlfn.STDEV.S(Results!E9,Results!P9) -> 0.014142136 | G8: =E8/SUM(E8:F8) -> 0.99561367 | H8: =((E8+E7))/2*(D8-D7)+H7 -> 107.88 | I8: =STDEV(Results!H9,Results!S9) -> 6.4148727 | J8: =(LN(E8)-LN(E7))/(D8-D7) -> 0.042771208 | K8: =AVERAGE(Results!K9,Results!V9) -> 0.21925 | L8: =STDEV(Results!K9,Results!V9) -> 0.0031819805 | M8: =((K8-K7)/(E8-E7))*J8*24000 -> 73.073986 | N8: =STDEV(Results!L9,Results!W9) -> 11.062514 | P8: 4 | Q8: =P8*24 -> 96 | R8: =(Results!E31+Results!P31)/2 -> 4.872 | S8: =_xlfn.STDEV.S(Results!E31,Results!P31) -> 1.5952329 | T8: =R8/SUM(R8:S8) -> 0.7533361 | U8: =((R8+R7))/2*(Q8-Q7)+U7 -> 124.488 | V8: =STDEV(Results!H31,Results!S31) -> 28.612369 | W8: =(LN(R8)-LN(R7))/(Q8-Q7) -> 0.049644268 | X8: =AVERAGE(Results!K31,Results!V31) -> 0.1552 | Y8: =STDEV(Results!K31,Results!V31) -> 0.0021213203 | Z8: =((X8-X7)/(R8-R7))*W8*24000 -> 31.929226 | AA8: =STDEV(Results!W31,Results!L31) -> 8.7700199 | AC8: 4 | AD8: =AC8*24 -> 96 | AE8: =(Results!E53+Results!P53)/2 -> 2.856 | AF8: =_xlfn.STDEV.S(Results!E53,Results!P53) -> 0.47517576 | AG8: =AE8/SUM(AE8:AF8) -> 0.85735494 | AH8: =((AE8+AE7))/2*(AD8-AD7)+AH7 -> 84.936 | AI8: =STDEV(Results!H53,Results!S53) -> 6.6864017 | AJ8: =(LN(AE8)-LN(AE7))/(AD8-AD7) -> 0.046526283 | AK8: =AVERAGE(Results!K53,Results!V53) -> 0.13075 | AL8: =STDEV(Results!K53,Results!V53) -> 0.013788582 | AM8: =((AK8-AK7)/(AE8-AE7))*AJ8*24000 -> 42.537762 | AN8: =STDEV(Results!L53,Results!W53) -> 15.0378 | AP8: 4 | AQ8: 3.885 | AR8: 0.11324752 | AS8: 0.10383108 | AT8: 0.001 | AU8: 26.200475 | AV8: 1.287197
A9: 32.5 | B9: 1 | C9: 5 | D9: =C9*24 -> 120 | E9: =(Results!E10+Results!P10)/2 -> 6.608 | F9: =_xlfn.STDEV.S(Results!E10,Results!P10) -> 0.15839192 | G9: =E9/SUM(E9:F9) -> 0.97659138 | H9: =((E9+E8))/2*(D9-D8)+H8 -> 225.696 | I9: =STDEV(Results!H10,Results!S10) -> 8.1458701 | J9: =(LN(E9)-LN(E8))/(D9-D8) -> 0.030083754 | K9: =AVERAGE(Results!K10,Results!V10) -> 0.36605 | L9: =STDEV(Results!K10,Results!V10) -> 0.022698128 | M9: =((K9-K8)/(E9-E8))*J9*24000 -> 31.192196 | N9: =STDEV(Results!L10,Results!W10) -> 4.5051965 | P9: 5 | Q9: =P9*24 -> 120 | R9: =(Results!E32+Results!P32)/2 -> 4.95 | S9: =_xlfn.STDEV.S(Results!E32,Results!P32) -> 1.4000714 | T9: =R9/SUM(R9:S9) -> 0.77951879 | U9: =((R9+R8))/2*(Q9-Q8)+U8 -> 242.352 | V9: =STDEV(Results!H32,Results!S32) -> 64.556021 | W9: =(LN(R9)-LN(R8))/(Q9-Q8) -> 0.00066179359 | X9: =AVERAGE(Results!K32,Results!V32) -> 0.24705 | Y9: =STDEV(Results!K32,Results!V32) -> 0.010818734 | Z9: =((X9-X8)/(R9-R8))*W9*24000 -> 18.703305 | AA9: =STDEV(Results!W32,Results!L32) -> 4.1284194 | AC9: 5 | AD9: =AC9*24 -> 120 | AE9: =(Results!E54+Results!P54)/2 -> 4.122 | AF9: =_xlfn.STDEV.S(Results!E54,Results!P54) -> 0.24607316 | AG9: =AE9/SUM(AE9:AF9) -> 0.94366551 | AH9: =((AE9+AE8))/2*(AD9-AD8)+AH8 -> 168.672 | AI9: =STDEV(Results!H54,Results!S54) -> 15.341389 | AJ9: =(LN(AE9)-LN(AE8))/(AD9-AD8) -> 0.015288185 | AK9: =AVERAGE(Results!K54,Results!V54) -> 0.1896 | AL9: =STDEV(Results!K54,Results!V54) -> 0.0087681241 | AM9: =((AK9-AK8)/(AE9-AE8))*AJ9*24000 -> 17.056108 | AN9: =STDEV(Results!L54,Results!W54) -> 4.6937331 | AP9: 5 | AQ9: 5.6833333 | AR9: 0.20966243 | AS9: 0.21084609 | AT9: 0.001 | AU9: 22.637688 | AV9: 2.8754328
A10: 32.5 | B10: 0 | C10: 6 | D10: =C10*24 -> 144 | E10: =(Results!E11+Results!P11)/2 -> 8 | F10: =_xlfn.STDEV.S(Results!E11,Results!P11) -> 1.1313708 | G10: =E10/SUM(E10:F10) -> 0.87610066 | H10: =((E10+E9))/2*(D10-D9)+H9 -> 400.992 | I10: =STDEV(Results!H11,Results!S11) -> 3.5298771 | J10: =(LN(E10)-LN(E9))/(D10-D9) -> 0.0079650211 | K10: =AVERAGE(Results!K11,Results!V11) -> 0.58195 | L10: =STDEV(Results!K11,Results!V11) -> 0.12734993 | M10: =((K10-K9)/(E10-E9))*J10*24000 -> 29.649104 | N10: =STDEV(Results!L11,Results!W11) -> 12.586471 | P10: 6 | Q10: =P10*24 -> 144 | R10: =(Results!E33+Results!P33)/2 -> 6.14 | S10: =_xlfn.STDEV.S(Results!E33,Results!P33) -> 0.93338095 | T10: =R10/SUM(R10:S10) -> 0.86804317 | U10: =((R10+R9))/2*(Q10-Q9)+U9 -> 375.432 | V10: =STDEV(Results!H33,Results!S33) -> 92.557449 | W10: =(LN(R10)-LN(R9))/(Q10-Q9) -> 0.0089765486 | X10: =AVERAGE(Results!K33,Results!V33) -> 0.45015 | Y10: =STDEV(Results!K33,Results!V33) -> 0.00417193 | Z10: =((X10-X9)/(R10-R9))*W10*24000 -> 36.76915 | AA10: =STDEV(Results!W33,Results!L33) -> 9.3468864 | AC10: 6 | AD10: =AC10*24 -> 144 | AE10: =(Results!E55+Results!P55)/2 -> 5.712 | AF10: =_xlfn.STDEV.S(Results!E55,Results!P55) -> 1.1992531 | AG10: =AE10/SUM(AE10:AF10) -> 0.8264782 | AH10: =((AE10+AE9))/2*(AD10-AD9)+AH9 -> 286.68 | AI10: =STDEV(Results!H55,Results!S55) -> 32.685304 | AJ10: =(LN(AE10)-LN(AE9))/(AD10-AD9) -> 0.013592948 | AK10: =AVERAGE(Results!K55,Results!V55) -> 0.4383 | AL10: =STDEV(Results!K55,Results!V55) -> 0.026304372 | AM10: =((AK10-AK9)/(AE10-AE9))*AJ10*24000 -> 51.027412 | AN10: =STDEV(Results!L55,Results!W55) -> 3.5406717 | AP10: 6 | AQ10: 8.9916667 | AR10: 1.1684213 | AS10: 0.39916134 | AT10: 0.001 | AU10: 26.113318 | AV10: 7.7650037
A11: 32.5 | B11: 1 | C11: 7 | D11: =C11*24 -> 168 | E11: =(Results!E12+Results!P12)/2 -> 10.525 | F11: =_xlfn.STDEV.S(Results!E12,Results!P12) -> 0.31819805 | G11: =E11/SUM(E11:F11) -> 0.97065459 | H11: =((E11+E10))/2*(D11-D10)+H10 -> 623.292 | I11: =STDEV(Results!H12,Results!S12) -> 13.287951 | J11: =(LN(E11)-LN(E10))/(D11-D10) -> 0.01142966 | K11: =AVERAGE(Results!K12,Results!V12) -> 0.79365 | L11: =STDEV(Results!K12,Results!V12) -> 0.035991735 | M11: =((K11-K10)/(E11-E10))*J11*24000 -> 22.998739 | N11: =STDEV(Results!L12,Results!W12) -> 18.985488 | P11: 7 | Q11: =P11*24 -> 168 | R11: =(Results!E34+Results!P34)/2 -> 8.775 | S11: =_xlfn.STDEV.S(Results!E34,Results!P34) -> 1.8031223 | T11: =R11/SUM(R11:S11) -> 0.82954231 | U11: =((R11+R10))/2*(Q11-Q10)+U10 -> 554.412 | V11: =STDEV(Results!H34,Results!S34) -> 125.39549 | W11: =(LN(R11)-LN(R10))/(Q11-Q10) -> 0.014878418 | X11: =AVERAGE(Results!K34,Results!V34) -> 0.60885 | Y11: =STDEV(Results!K34,Results!V34) -> 0.058194888 | Z11: =((X11-X10)/(R11-R10))*W11*24000 -> 21.506231 | AA11: =STDEV(Results!W34,Results!L34) -> 3.4989397 | AC11: 7 | AD11: =AC11*24 -> 168 | AE11: =(Results!E56+Results!P56)/2 -> 7.76 | AF11: =_xlfn.STDEV.S(Results!E56,Results!P56) -> 1.0748023 | AG11: =AE11/SUM(AE11:AF11) -> 0.8783445 | AH11: =((AE11+AE10))/2*(AD11-AD10)+AH10 -> 448.344 | AI11: =STDEV(Results!H56,Results!S56) -> 34.178713 | AJ11: =(LN(AE11)-LN(AE10))/(AD11-AD10) -> 0.012767213 | AK11: =AVERAGE(Results!K56,Results!V56) -> 0.58095 | AL11: =STDEV(Results!K56,Results!V56) -> 0.063144636 | AM11: =((AK11-AK10)/(AE11-AE10))*AJ11*24000 -> 21.34269 | AN11: =STDEV(Results!L56,Results!W56) -> 14.039275 | AP11: 7 | AQ11: 11.266667 | AR11: 0.028867513 | AS11: 0.79486249 | AT11: 0.001 | AU11: 39.230994 | AV11: 22.717569
A12: 32.5 | B12: 0 | C12: 8 | D12: =C12*24 -> 192 | E12: =(Results!E13+Results!P13)/2 -> 10.725 | F12: =_xlfn.STDEV.S(Results!E13,Results!P13) -> 0.31819805 | G12: =E12/SUM(E12:F12) -> 0.97118606 | H12: =((E12+E11))/2*(D12-D11)+H11 -> 878.292 | I12: =STDEV(Results!H13,Results!S13) -> 13.287951 | J12: =(LN(E12)-LN(E11))/(D12-D11) -> 0.00078433689 | K12: =AVERAGE(Results!K13,Results!V13) -> 1.257 | L12: =STDEV(Results!K13,Results!V13) -> 0.19940411 | M12: =((K12-K11)/(E12-E11))*J12*24000 -> 43.610699 | N12: =STDEV(Results!L13,Results!W13) -> 15.374543 | P12: 8 | Q12: =P12*24 -> 192 | R12: =(Results!E35+Results!P35)/2 -> 9.75 | S12: =_xlfn.STDEV.S(Results!E35,Results!P35) -> 0.70710678 | T12: =R12/SUM(R12:S12) -> 0.93238027 | U12: =((R12+R11))/2*(Q12-Q11)+U11 -> 776.712 | V12: =STDEV(Results!H35,Results!S35) -> 155.51824 | W12: =(LN(R12)-LN(R11))/(Q12-Q11) -> 0.0043900215 | X12: =AVERAGE(Results!K35,Results!V35) -> 0.72875 | Y12: =STDEV(Results!K35,Results!V35) -> 0.032880465 | Z12: =((X12-X11)/(R12-R11))*W12*24000 -> 12.956642 | AA12: =STDEV(Results!W35,Results!L35) -> 4.5710264 | AC12: 8 | AD12: =AC12*24 -> 192 | AE12: =(Results!E57+Results!P57)/2 -> 9.8 | AF12: =_xlfn.STDEV.S(Results!E57,Results!P57) -> 0.79195959 | AG12: =AE12/SUM(AE12:AF12) -> 0.92523012 | AH12: =((AE12+AE11))/2*(AD12-AD11)+AH11 -> 659.064 | AI12: =STDEV(Results!H57,Results!S57) -> 30.784601 | AJ12: =(LN(AE12)-LN(AE11))/(AD12-AD11) -> 0.0097250021 | AK12: =AVERAGE(Results!K57,Results!V57) -> 0.7329 | AL12: =STDEV(Results!K57,Results!V57) -> 0.040446508 | AM12: =((AK12-AK11)/(AE12-AE11))*AJ12*24000 -> 17.384871 | AN12: =STDEV(Results!L57,Results!W57) -> 12.309797 | AP12: 8 | AQ12: 12.875 | AR12: 0.30413813 | AS12: 1.2860754 | AT12: 0.001 | AU12: 40.754566 | AV12: 7.282879
A13: 32.5 | B13: 1 | C13: 9 | D13: =C13*24 -> 216 | E13: =(Results!E14+Results!P14)/2 -> 10.475 | F13: =_xlfn.STDEV.S(Results!E14,Results!P14) -> 0.38890873 | G13: =E13/SUM(E13:F13) -> 0.96420177 | H13: =((E13+E12))/2*(D13-D12)+H12 -> 1132.692 | I13: =STDEV(Results!H14,Results!S14) -> 12.439422 | J13: =(LN(E13)-LN(E12))/(D13-D12) -> -0.00098274996 | K13: =AVERAGE(Results!K14,Results!V14) -> 1.5045 | L13: =STDEV(Results!K14,Results!V14) -> 0.11525841 | M13: =((K13-K12)/(E13-E12))*J13*24000 -> 23.350139 | N13: =STDEV(Results!L14,Results!W14) -> 8.0242312 | P13: 9 | Q13: =P13*24 -> 216 | R13: =(Results!E36+Results!P36)/2 -> 10.85 | S13: =_xlfn.STDEV.S(Results!E36,Results!P36) -> 1.2020815 | T13: =R13/SUM(R13:S13) -> 0.90025943 | U13: =((R13+R12))/2*(Q13-Q12)+U12 -> 1023.912 | V13: =STDEV(Results!H36,Results!S36) -> 178.4285 | W13: =(LN(R13)-LN(R12))/(Q13-Q12) -> 0.0044540748 | X13: =AVERAGE(Results!K36,Results!V36) -> 0.93445 | Y13: =STDEV(Results!K36,Results!V36) -> 0.017606959 | Z13: =((X13-X12)/(R13-R12))*W13*24000 -> 19.989888 | AA13: =STDEV(Results!W36,Results!L36) -> 6.7747062 | AC13: 9 | AD13: =AC13*24 -> 216 | AE13: =(Results!E58+Results!P58)/2 -> 9.78 | AF13: =_xlfn.STDEV.S(Results!E58,Results!P58) -> 0.82024387 | AG13: =AE13/SUM(AE13:AF13) -> 0.92262028 | AH13: =((AE13+AE12))/2*(AD13-AD12)+AH12 -> 894.024 | AI13: =STDEV(Results!H58,Results!S58) -> 30.44519 | AJ13: =(LN(AE13)-LN(AE12))/(AD13-AD12) -> -8.5120901e-05 | AK13: =AVERAGE(Results!K58,Results!V58) -> 0.90975 | AL13: =STDEV(Results!K58,Results!V58) -> 0.17854446 | AM13: =((AK13-AK12)/(AE13-AE12))*AJ13*24000 -> 18.064358 | AN13: =STDEV(Results!L58,Results!W58) -> 14.149216 | AP13: 9 | AQ13: 13.033333 | AR13: 1.3096596 | AS13: 1.3960408 | AT13: 0.001 | AU13: 8.4889126 | AV13: 25.904813
A14: 32.5 | B14: 0 | C14: 10 | D14: =C14*24 -> 240 | E14: =(Results!E15+Results!P15)/2 -> 10.225 | F14: =_xlfn.STDEV.S(Results!E15,Results!P15) -> 0.31819805 | G14: =E14/SUM(E14:F14) -> 0.96981959 | H14: =((E14+E13))/2*(D14-D13)+H13 -> 1381.092 | I14: =STDEV(Results!H15,Results!S15) -> 11.590894 | J14: =(LN(E14)-LN(E13))/(D14-D13) -> -0.0010064902 | K14: =AVERAGE(Results!K15,Results!V15) -> 1.8145 | L14: =STDEV(Results!K15,Results!V15) -> 0.089802561 | M14: =((K14-K13)/(E14-E13))*J14*24000 -> 29.953147 | N14: =STDEV(Results!L15,Results!W15) -> 19.911706 | P14: 10 | Q14: =P14*24 -> 240 | R14: =(Results!E37+Results!P37)/2 -> 10.55 | S14: =_xlfn.STDEV.S(Results!E37,Results!P37) -> 0.14142136 | T14: =R14/SUM(R14:S14) -> 0.98677245 | U14: =((R14+R13))/2*(Q14-Q13)+U13 -> 1280.712 | V14: =STDEV(Results!H37,Results!S37) -> 191.15642 | W14: =(LN(R14)-LN(R13))/(Q14-Q13) -> -0.0011683008 | X14: =AVERAGE(Results!K37,Results!V37) -> 1.285 | Y14: =STDEV(Results!K37,Results!V37) -> 0.057982756 | Z14: =((X14-X13)/(R14-R13))*W14*24000 -> 32.763829 | AA14: =STDEV(Results!W37,Results!L37) -> 5.3905752 | AC14: 10 | AD14: =AC14*24 -> 240 | AE14: =(Results!E59+Results!P59)/2 -> 9.02 | AF14: =_xlfn.STDEV.S(Results!E59,Results!P59) -> 1.7253405 | AG14: =AE14/SUM(AE14:AF14) -> 0.83943361 | AH14: =((AE14+AE13))/2*(AD14-AD13)+AH13 -> 1119.624 | AI14: =STDEV(Results!H59,Results!S59) -> 41.30635 | AJ14: =(LN(AE14)-LN(AE13))/(AD14-AD13) -> -0.0033706312 | AK14: =AVERAGE(Results!K59,Results!V59) -> 1.4966 | AL14: =STDEV(Results!K59,Results!V59) -> 0.19714137 | AM14: =((AK14-AK13)/(AE14-AE13))*AJ14*24000 -> 62.464893 | AN14: =STDEV(Results!L59,Results!W59) -> 1.286245 | AP14: 10 | AQ14: 13.333333 | AR14: 0.22684429 | AS14: 1.8371268 | AT14: 0.16266976 | AU14: 33.459293 | AV14: 10.781272
A15: 32.5 | B15: 1 | C15: 11 | D15: =C15*24 -> 264 | E15: =(Results!E16+Results!P16)/2 -> 10.275 | F15: =_xlfn.STDEV.S(Results!E16,Results!P16) -> 1.0253048 | G15: =E15/SUM(E15:F15) -> 0.90926751 | H15: =((E15+E14))/2*(D15-D14)+H14 -> 1627.092 | I15: =STDEV(Results!H16,Results!S16) -> 27.712929 | J15: =(LN(E15)-LN(E14))/(D15-D14) -> 0.00020325244 | K15: =AVERAGE(Results!K16,Results!V16) -> 1.9945 | L15: =STDEV(Results!K16,Results!V16) -> 0.0417193 | M15: =((K15-K14)/(E15-E14))*J15*24000 -> 17.56101 | N15: =STDEV(Results!L16,Results!W16) -> 14.014613 | P15: 11 | Q15: =P15*24 -> 264 | R15: =(Results!E38+Results!P38)/2 -> 8.7 | S15: =_xlfn.STDEV.S(Results!E38,Results!P38) -> 0.77781746 | T15: =R15/SUM(R15:S15) -> 0.91793285 | U15: =((R15+R14))/2*(Q15-Q14)+U14 -> 1511.712 | V15: =STDEV(Results!H38,Results!S38) -> 180.12555 | W15: =(LN(R15)-LN(R14))/(Q15-Q14) -> -0.0080334514 | X15: =AVERAGE(Results!K38,Results!V38) -> 1.695 | Y15: =STDEV(Results!K38,Results!V38) -> 0.0084852814 | Z15: =((X15-X14)/(R15-R14))*W15*24000 -> 42.729277 | AA15: =STDEV(Results!W38,Results!L38) -> 9.0861739 | AC15: 11 | AD15: =AC15*24 -> 264 | AE15: =(Results!E60+Results!P60)/2 -> 6.88 | AF15: =_xlfn.STDEV.S(Results!E60,Results!P60) -> 0.11313708 | AG15: =AE15/SUM(AE15:AF15) -> 0.9838217 | AH15: =((AE15+AE14))/2*(AD15-AD14)+AH14 -> 1310.424 | AI15: =STDEV(Results!H60,Results!S60) -> 60.652791 | AJ15: =(LN(AE15)-LN(AE14))/(AD15-AD14) -> -0.011284403 | AK15: =AVERAGE(Results!K60,Results!V60) -> 1.85 | AL15: =STDEV(Results!K60,Results!V60) -> 0.093338095 | AM15: =((AK15-AK14)/(AE15-AE14))*AJ15*24000 -> 44.724204 | AN15: =STDEV(Results!L60,Results!W60) -> 17.375727 | AP15: 11 | AQ15: 10.516667 | AR15: 0.65208001 | AS15: 2.4196293 | AT15: 0.22380564 | AU15: 49.076183 | AV15: 26.859407
A16: 32.5 | B16: 0 | C16: 12 | D16: =C16*24 -> 288 | E16: =(Results!E17+Results!P17)/2 -> 8.45 | F16: =_xlfn.STDEV.S(Results!E17,Results!P17) -> 0.91923882 | G16: =E16/SUM(E16:F16) -> 0.90188757 | H16: =((E16+E15))/2*(D16-D15)+H15 -> 1851.792 | I16: =STDEV(Results!H17,Results!S17) -> 51.047453 | J16: =(LN(E16)-LN(E15))/(D16-D15) -> -0.008147805 | K16: =AVERAGE(Results!K17,Results!V17) -> 1.8795 | L16: =STDEV(Results!K17,Results!V17) -> 0.00070710678 | M16: =((K16-K15)/(E16-E15))*J16*24000 -> -12.32216 | N16: =STDEV(Results!L17,Results!W17) -> 5.8609894 | P16: 12 | Q16: =P16*24 -> 288 | R16: =(Results!E39+Results!P39)/2 -> 7.35 | S16: =_xlfn.STDEV.S(Results!E39,Results!P39) -> 0.21213203 | T16: =R16/SUM(R16:S16) -> 0.97194812 | U16: =((R16+R15))/2*(Q16-Q15)+U15 -> 1704.312 | V16: =STDEV(Results!H39,Results!S39) -> 173.33733 | W16: =(LN(R16)-LN(R15))/(Q16-Q15) -> -0.0070259464 | X16: =AVERAGE(Results!K39,Results!V39) -> 1.875 | Y16: =STDEV(Results!K39,Results!V39) -> 0.1767767 | Z16: =((X16-X15)/(R16-R15))*W16*24000 -> 22.483028 | AA16: =STDEV(Results!W39,Results!L39) -> 22.446079 | AC16: 12 | AD16: =AC16*24 -> 288 | AE16: =(Results!E61+Results!P61)/2 -> 8.34 | AF16: =_xlfn.STDEV.S(Results!E61,Results!P61) -> 0.1979899 | AG16: =AE16/SUM(AE16:AF16) -> 0.97681071 | AH16: =((AE16+AE15))/2*(AD16-AD15)+AH15 -> 1493.064 | AI16: =STDEV(Results!H61,Results!S61) -> 61.671025 | AJ16: =(LN(AE16)-LN(AE15))/(AD16-AD15) -> 0.0080185235 | AK16: =AVERAGE(Results!K61,Results!V61) -> 2.307445 | AL16: =STDEV(Results!K61,Results!V61) -> 0.15634838 | AM16: =((AK16-AK15)/(AE16-AE15))*AJ16*24000 -> 60.296441 | AN16: =STDEV(Results!L61,Results!W61) -> 8.047276 | AP16: 12 | AQ16: 13.016667 | AR16: 2.5594596 | AS16: 2.4659908 | AT16: 0.001 | AU16: 3.9549946 | AV16: 19.474339
... A18: 32.5 | B18: 0 | C18: 14 | D18: =C18*24 -> 336 | E18: =(Results!E19+Results!P19)/2 -> 5.6 | F18: =_xlfn.STDEV.S(Results!E19,Results!P19) -> 0.62225397 | G18: =E18/SUM(E18:F18) -> 0.89999541 | H18: =((E18+E17))/2*(D18-D17)+H17 -> 2212.992 | I18: =STDEV(Results!H19,Results!S19) -> 28.306899 | J18: =(LN(E18)-LN(E17))/(D18-D17) -> -0.014991461 | K18: =AVERAGE(Results!K19,Results!V19) -> 1.783 | L18: =STDEV(Results!K19,Results!V19) -> 0.026870058 | M18: =((K18-K17)/(E18-E17))*J18*24000 -> -10.608391 | N18: =STDEV(Results!L19,Results!W19) -> 11.25032 | P18: 14 | Q18: =P18*24 -> 336 | R18: =(Results!E41+Results!P41)/2 -> 6.66 | S18: =_xlfn.STDEV.S(Results!E41,Results!P41) -> 0.36769553 | T18: =R18/SUM(R18:S18) -> 0.94767908 | U18: =((R18+R17))/2*(Q18-Q17)+U17 -> 2038.032 | V18: =STDEV(Results!H41,Results!S41) -> 174.86468 | W18: =(LN(R18)-LN(R17))/(Q18-Q17) -> -0.0014750803 | X18: =AVERAGE(Results!K41,Results!V41) -> 1.844 | Y18: =STDEV(Results!K41,Results!V41) -> 0.1046518 | Z18: =((X18-X17)/(R18-R17))*W18*24000 -> -12.390674 | AA18: =STDEV(Results!W41,Results!L41) -> 12.100133 | AC18: 14 | AD18: =AC18*24 -> 336 | AE18: =(Results!E63+Results!P63)/2 -> 5.68 | AF18: =_xlfn.STDEV.S(Results!E63,Results!P63) -> 0.11313708 | AG18: =AE18/SUM(AE18:AF18) -> 0.9804705 | AH18: =((AE18+AE17))/2*(AD18-AD17)+AH17 -> 1824.504 | AI18: =STDEV(Results!H63,Results!S63) -> 95.272739 | AJ18: =(LN(AE18)-LN(AE17))/(AD18-AD17) -> -0.0074988075 | AK18: =AVERAGE(Results!K63,Results!V63) -> 2.662 | AL18: =STDEV(Results!K63,Results!V63) -> 0.084852814 | AM18: =((AK18-AK17)/(AE18-AE17))*AJ18*24000 -> 7.2309929 | AN18: =STDEV(Results!L63,Results!W63) -> 23.860945 | AP18: 14 | AQ18: 8.5333333 | AR18: 0.76865684 | AS18: 2.461697 | AT18: 0.20696212 | AU18: -0.98902126 | AV18: -21.948094
